2024-05-20 08:40:34,311 ERROR scheduler Exception in Enqueue Events for Site my-site.test
Traceback (most recent call last):
  File "/home/mbw2024/Documents/test/apps/frappe/frappe/utils/scheduler.py", line 75, in enqueue_events_for_site
    if is_scheduler_inactive():
       ^^^^^^^^^^^^^^^^^^^^^^^
  File "/home/mbw2024/Documents/test/apps/frappe/frappe/utils/scheduler.py", line 117, in is_scheduler_inactive
    if is_scheduler_disabled(verbose=verbose):
       ^^^^^^^^^^^^^^^^^^^^^^^^^^^^^^^^^^^^^^
  File "/home/mbw2024/Documents/test/apps/frappe/frappe/utils/scheduler.py", line 130, in is_scheduler_disabled
    frappe.db.get_single_value("System Settings", "enable_scheduler")
  File "/home/mbw2024/Documents/test/apps/frappe/frappe/database/database.py", line 841, in get_single_value
    ).run()
      ^^^^^
  File "/home/mbw2024/Documents/test/apps/frappe/frappe/query_builder/utils.py", line 87, in execute_query
    result = frappe.db.sql(query, params, *args, **kwargs)  # nosemgrep
             ^^^^^^^^^^^^^^^^^^^^^^^^^^^^^^^^^^^^^^^^^^^^^
  File "/home/mbw2024/Documents/test/apps/frappe/frappe/database/database.py", line 234, in sql
    self._cursor.execute(query, values)
  File "/home/mbw2024/Documents/test/env/lib/python3.11/site-packages/pymysql/cursors.py", line 153, in execute
    result = self._query(query)
             ^^^^^^^^^^^^^^^^^^
  File "/home/mbw2024/Documents/test/env/lib/python3.11/site-packages/pymysql/cursors.py", line 322, in _query
    conn.query(q)
  File "/home/mbw2024/Documents/test/env/lib/python3.11/site-packages/pymysql/connections.py", line 558, in query
    self._affected_rows = self._read_query_result(unbuffered=unbuffered)
                          ^^^^^^^^^^^^^^^^^^^^^^^^^^^^^^^^^^^^^^^^^^^^^^
  File "/home/mbw2024/Documents/test/env/lib/python3.11/site-packages/pymysql/connections.py", line 822, in _read_query_result
    result.read()
  File "/home/mbw2024/Documents/test/env/lib/python3.11/site-packages/pymysql/connections.py", line 1200, in read
    first_packet = self.connection._read_packet()
                   ^^^^^^^^^^^^^^^^^^^^^^^^^^^^^^
  File "/home/mbw2024/Documents/test/env/lib/python3.11/site-packages/pymysql/connections.py", line 772, in _read_packet
    packet.raise_for_error()
  File "/home/mbw2024/Documents/test/env/lib/python3.11/site-packages/pymysql/protocol.py", line 221, in raise_for_error
    err.raise_mysql_exception(self._data)
  File "/home/mbw2024/Documents/test/env/lib/python3.11/site-packages/pymysql/err.py", line 143, in raise_mysql_exception
    raise errorclass(errno, errval)
pymysql.err.ProgrammingError: (1146, "Table '_57886cb1bd7fbf3e.tabSingles' doesn't exist")
